Workbook

Sheet TOTAL DONATION PER YEAR
A3: Graduation Year | B3: Total Donation (₦)
A4: 2022 | B4: 114031
A5: 2023 | B5: 148762
A6: 2024 | B6: 100444
A7: 2025 | B7: 120076 | D7: Graduation Year | E7: Sum of Total Donation (₦)
A8: Grand Total | B8: 483313 | D8: 2022 | E8: 114031
D9: 2023 | E9: 148762
D10: 2024 | E10: 100444
D11: 2025 | E11: 120076
D12: Grand Total | E12: 483313

Sheet CGPA AND EMPLOYMENT CHART
A3: Employment Status | B3: AVERAGE CGPA
A4: Employed | B4: 3.717037
A5: Unemployed | B5: 3.4334783
A6: Grand Total | B6: 3.5866

Sheet VISUALS
A3: Graduation Year | B3: Average of Monthly Salary
A4: 2022 | B4: 101862.62
A5: 2023 | B5: 195008.07
A6: 2024 | B6: 124693.5
A7: 2025 | B7: 100710
A8: Grand Total | B8: 134095.8

Sheet UNEMPLOYED AND EMPLOYED
A3: Employment Status | B3: Count of Full Name
A4: Employed | B4: 27
A5: Unemployed | B5: 23
A6: Grand Total | B6: 50

Sheet FINAL PROECT
A1: Full Name | B1: Gender | C1: Graduation Year | D1: CGPA | E1: Country | F1: Employment Status | G1: Monthly Salary | H1: High Earner | I1: Donation (₦) | J1: Donors | K1: Date of Donation | L1: Notes
A2: Kimberly Sanchez | B2: Male | C2: 2022 | D2: 3.98 | E2: Kenya | F2: Employed | G2: 498432 | H2: =IF(G2>200000,"YES","NO") -> YES | I2: 0 | J2: =IF(I2>0,"YES","NO") -> NO | L2: Here writer policy news range successful simply.
A3: Peter Callahan Jr. | B3: Female | C3: 2023 | D3: 4.05 | E3: Nigeria | F3: Employed | G3: 480861 | H3: =IF(G3>200000,"YES","NO") -> YES | I3: 3103 | J3: =IF(I3>0,"YES","NO") -> YES | K3: 45262 | L3: Others his other life edge network.
A4: Jeremy Thornton | B4: Female | C4: 2023 | D4: 4.91 | E4: Egypt | F4: Employed | G4: 442154 | H4: =IF(G4>200000,"YES","NO") -> YES | I4: 0 | J4: =IF(I4>0,"YES","NO") -> NO | L4: Act away third tough nation strong old.
A5: Valerie Gill | B5: Female | C5: 2025 | D5: 2.43 | E5: Ghana | F5: Employed | G5: 440588 | H5: =IF(G5>200000,"YES","NO") -> YES | I5: 37789 | J5: =IF(I5>0,"YES","NO") -> YES | K5: 45532 | L5: That fear police participant.
A6: John Daniel | B6: Male | C6: 2023 | D6: 4.63 | E6: Nigeria | F6: Employed | G6: 433730 | H6: =IF(G6>200000,"YES","NO") -> YES | I6: 0 | J6: =IF(I6>0,"YES","NO") -> NO | L6: Art rock song body.
A7: Michelle Ross | B7: Male | C7: 2024 | D7: 3.3 | E7: South Africa | F7: Employed | G7: 428584 | H7: =IF(G7>200000,"YES","NO") -> YES | I7: 48164 | J7: =IF(I7>0,"YES","NO") -> YES | K7: 45659 | L7: Just military building different full open.
A8: Emily Obrien | B8: Female | C8: 2024 | D8: 3.84 | E8: Egypt | F8: Employed | G8: 400152 | H8: =IF(G8>200000,"YES","NO") -> YES | I8: 37346 | J8: =IF(I8>0,"YES","NO") -> YES | K8: 45535 | L8: History office effort remember.
A9: James Brown | B9: Male | C9: 2023 | D9: 2.67 | E9: Kenya | F9: Employed | G9: 358443 | H9: =IF(G9>200000,"YES","NO") -> YES | I9: 0 | J9: =IF(I9>0,"YES","NO") -> NO | L9: Able hospital unit size expect recent.
A10: Erik Williams | B10: Male | C10: 2023 | D10: 2.84 | E10: South Africa | F10: Employed | G10: 332713 | H10: =IF(G10>200000,"YES","NO") -> YES | I10: 9671 | J10: =IF(I10>0,"YES","NO") -> YES | K10: 45508 | L10: Try most arm meet surface attention attack.
A11: Kendra Contreras | B11: Male | C11: 2022 | D11: 4.91 | E11: Ghana | F11: Employed | G11: 263078 | H11: =IF(G11>200000,"YES","NO") -> YES | I11: 32826 | J11: =IF(I11>0,"YES","NO") -> YES | K11: 45568 | L11: Use billion there enough threat.
A12: David Bradley | B12: Male | C12: 2023 | D12: 3.88 | E12: South Africa | F12: Employed | G12: 251728 | H12: =IF(G12>200000,"YES","NO") -> YES | I12: 26009 | J12: =IF(I12>0,"YES","NO") -> YES | K12: 45199 | L12: Rule staff within mouth.
A13: Andrew Stewart | B13: Female | C13: 2024 | D13: 3.36 | E13: Kenya | F13: Employed | G13: 244081 | H13: =IF(G13>200000,"YES","NO") -> YES | I13: 0 | J13: =IF(I13>0,"YES","NO") -> NO | L13: At tree note responsibility defense.
A14: Ms. Teresa Wilson | B14: Female | C14: 2023 | D14: 4.8 | E14: Nigeria | F14: Employed | G14: 243738 | H14: =IF(G14>200000,"YES","NO") -> YES | I14: 0 | J14: =IF(I14>0,"YES","NO") -> NO | L14: Condition while enter board its.
A15: Jamie Adkins | B15: Male | C15: 2025 | D15: 4.49 | E15: Nigeria | F15: Employed | G15: 224879 | H15: =IF(G15>200000,"YES","NO") -> YES | I15: 9573 | J15: =IF(I15>0,"YES","NO") -> YES | K15: 45273 | L15: Notice image street fight decision size parent focus.
A16: Timothy Ryan | B16: Male | C16: 2023 | D16: 2.79 | E16: Nigeria | F16: Employed | G16: 192788 | H16: =IF(G16>200000,"YES","NO") -> NO | I16: 0 | J16: =IF(I16>0,"YES","NO") -> NO | L16: Hair attorney professional form finish.
A17: Joshua Taylor | B17: Male | C17: 2023 | D17: 3.98 | E17: Egypt | F17: Employed | G17: 188966 | H17: =IF(G17>200000,"YES","NO") -> NO | I17: 35581 | J17: =IF(I17>0,"YES","NO") -> YES | K17: 45280 | L17: Leg themselves away space task.
A18: Paula Robinson | B18: Male | C18: 2024 | D18: 4.34 | E18: South Africa | F18: Employed | G18: 174118 | H18: =IF(G18>200000,"YES","NO") -> NO | I18: 0 | J18: =IF(I18>0,"YES","NO") -> NO | L18: Let newspaper true building card let most.
A19: Brandon Hall | B19: Male | C19: 2025 | D19: 2.1 | E19: Nigeria | F19: Employed | G19: 171981 | H19: =IF(G19>200000,"YES","NO") -> NO | I19: 0 | J19: =IF(I19>0,"YES","NO") -> NO | L19: Ago current practice nation determine operation speak according.
A20: Dr. Marvin Thomas Jr. | B20: Female | C20: 2022 | D20: 3.83 | E20: Ghana | F20: Employed | G20: 135669 | H20: =IF(G20>200000,"YES","NO") -> NO | I20: 31294 | J20: =IF(I20>0,"YES","NO") -> YES | K20: 45716 | L20: Much section investment on gun young catch.
A21: Daniel Jones | B21: Male | C21: 2022 | D21: 4.61 | E21: Kenya | F21: Employed | G21: 130131 | H21: =IF(G21>200000,"YES","NO") -> NO | I21: 0 | J21: =IF(I21>0,"YES","NO") -> NO | L21: Arrive attack all form method everything magazine much.
A22: Allison Hill | B22: Male | C22: 2022 | D22: 4.22 | E22: Ghana | F22: Employed | G22: 123158 | H22: =IF(G22>200000,"YES","NO") -> NO | I22: 0 | J22: =IF(I22>0,"YES","NO") -> NO | L22: Cause bill scientist nation opportunity.
A23: Michael Dixon | B23: Male | C23: 2025 | D23: 3.66 | E23: South Africa | F23: Employed | G23: 108654 | H23: =IF(G23>200000,"YES","NO") -> NO | I23: 0 | J23: =IF(I23>0,"YES","NO") -> NO | L23: Probably exist professional people.
A24: Jennifer David | B24: Male | C24: 2025 | D24: 4.42 | E24: Ghana | F24: Employed | G24: 100819 | H24: =IF(G24>200000,"YES","NO") -> NO | I24: 44187 | J24: =IF(I24>0,"YES","NO") -> YES | K24: 45580 | L24: Often always bank price north.
A25: Matthew Ross | B25: Male | C25: 2022 | D25: 3.37 | E25: Egypt | F25: Employed | G25: 88409 | H25: =IF(G25>200000,"YES","NO") -> NO | I25: 0 | J25: =IF(I25>0,"YES","NO") -> NO | L25: Ten whom evidence political hundred.
A26: Rachel Stanley | B26: Male | C26: 2022 | D26: 2.21 | E26: Nigeria | F26: Employed | G26: 85337 | H26: =IF(G26>200000,"YES","NO") -> NO | I26: 3058 | J26: =IF(I26>0,"YES","NO") -> YES | K26: 45516 | L26: Couple design around save.
A27: Dean Santiago | B27: Female | C27: 2025 | D27: 3.23 | E27: Nigeria | F27: Employed | G27: 81778 | H27: =IF(G27>200000,"YES","NO") -> NO | I27: 27386 | J27: =IF(I27>0,"YES","NO") -> YES | K27: 45382 | L27: Enter capital population lead upon.
A28: Cameron Parker | B28: Male | C28: 2025 | D28: 3.51 | E28: Egypt | F28: Employed | G28: 79821 | H28: =IF(G28>200000,"YES","NO") -> NO | I28: 0 | J28: =IF(I28>0,"YES","NO") -> NO | L28: Together decide economic.
A29: Melissa Peterson | B29: Male | C29: 2025 | D29: 2.66 | E29: Egypt | F29: Unemployed | G29: 0 | H29: =IF(G29>200000,"YES","NO") -> NO | I29: 0 | J29: =IF(I29>0,"YES","NO") -> NO | L29: Democratic shake bill here.
A30: Gregory Baker | B30: Female | C30: 2024 | D30: 2.83 | E30: Ghana | F30: Unemployed | G30: 0 | H30: =IF(G30>200000,"YES","NO") -> NO | I30: 0 | J30: =IF(I30>0,"YES","NO") -> NO | L30: Role movie win.
A31: Juan Calderon | B31: Female | C31: 2022 | D31: 3.08 | E31: Kenya | F31: Unemployed | G31: 0 | H31: =IF(G31>200000,"YES","NO") -> NO | I31: 3847 | J31: =IF(I31>0,"YES","NO") -> YES | K31: 45618 | L31: Officer relate animal direction eye bag.
A32: Brian Ramirez | B32: Male | C32: 2025 | D32: 2.24 | E32: Kenya | F32: Unemployed | G32: 0 | H32: =IF(G32>200000,"YES","NO") -> NO | I32: 0 | J32: =IF(I32>0,"YES","NO") -> NO | L32: Class great prove reduce raise author.
A33: Melanie Wilson | B33: Female | C33: 2024 | D33: 2.2 | E33: Egypt | F33: Unemployed | G33: 0 | H33: =IF(G33>200000,"YES","NO") -> NO | I33: 14934 | J33: =IF(I33>0,"YES","NO") -> YES | K33: 45825 | L33: Seem shoulder future fall citizen about reveal.
A34: Phillip Ryan | B34: Female | C34: 2025 | D34: 3.09 | E34: Ghana | F34: Unemployed | G34: 0 | H34: =IF(G34>200000,"YES","NO") -> NO | I34: 0 | J34: =IF(I34>0,"YES","NO") -> NO | L34: Truth out major born guy world southern.
A35: Matthew Arroyo | B35: Female | C35: 2022 | D35: 4.04 | E35: Nigeria | F35: Unemployed | G35: 0 | H35: =IF(G35>200000,"YES","NO") -> NO | I35: 43006 | J35: =IF(I35>0,"YES","NO") -> YES | K35: 45266 | L35: Month parent who up sense.
A36: Sonya Johnston | B36: Male | C36: 2024 | D36: 3.47 | E36: Nigeria | F36: Unemployed | G36: 0 | H36: =IF(G36>200000,"YES","NO") -> NO | I36: 0 | J36: =IF(I36>0,"YES","NO") -> NO | L36: Six space couple best issue.
A37: Matthew Fernandez | B37: Male | C37: 2023 | D37: 4.14 | E37: South Africa | F37: Unemployed | G37: 0 | H37: =IF(G37>200000,"YES","NO") -> NO | I37: 29711 | J37: =IF(I37>0,"YES","NO") -> YES | K37: 45149 | L37: Unit support coach magazine.
A38: Alexandra Howell | B38: Male | C38: 2023 | D38: 2.57 | E38: Egypt | F38: Unemployed | G38: 0 | H38: =IF(G38>200000,"YES","NO") -> NO | I38: 10186 | J38: =IF(I38>0,"YES","NO") -> YES | K38: 45575 | L38: Available defense enter value.
A39: Sherry Wood | B39: Male | C39: 2024 | D39: 3.39 | E39: Nigeria | F39: Unemployed | G39: 0 | H39: =IF(G39>200000,"YES","NO") -> NO | I39: 0 | J39: =IF(I39>0,"YES","NO") -> NO | L39: Just myself few worker.
A40: Brittney Campbell | B40: Male | C40: 2025 | D40: 4.71 | E40: Ghana | F40: Unemployed | G40: 0 | H40: =IF(G40>200000,"YES","NO") -> NO | I40: 1141 | J40: =IF(I40>0,"YES","NO") -> YES | K40: 45301 | L40: Data plant enough major town suffer.
...

Sheet ANALYSIS
A2: TOTAL AMOUNT DONATED BY ALL STUDENTS :
A3: =SUM('FINAL PROECT'!I2:I51) -> 483313
A5: STUDENTS AVERAGE CGPA :
A6: =AVERAGE('FINAL PROECT'!D2:D51) -> 3.5866
A8: HOW MANY STUDENTS ARE CURRENTLY EMPLOYED :
A9: =COUNTIF('FINAL PROECT'!F2:F51,"Employed") -> 27
A11: HIGEST SALARY PAID
A12: =MAX('FINAL PROECT'!G2:G51) -> 498432
A14: LOWEST SALARY PAID
A15: =_xlfn.MINIFS('FINAL PROECT'!G2:G51,'FINAL PROECT'!F2:F51,"Employed") -> 79821

Sheet 2024 GRADUATING STUDENTS
A1: FULL NAME | B1: GENDER | C1: GRADUATION YEAR | D1: CGPA | E1: COUNTRY | F1: EMOLOYMENT STATUS | G1: MONTHLY SALARY | H1: HIGH EARNERS | I1: DONATION | J1: DONORS | K1: DATE OF DONATION | L1: NOTES
A2: Gregory Baker | B2: Female | C2: 2024 | D2: 2.83 | E2: Ghana | F2: Unemployed | G2: 0 | H2: NO | I2: 0 | J2: NO | L2: Role movie win.
A3: Andrew Stewart | B3: Female | C3: 2024 | D3: 3.36 | E3: Kenya | F3: Employed | G3: 244081 | H3: YES | I3: 0 | J3: NO | L3: At tree note responsibility defense.
A4: Melanie Wilson | B4: Female | C4: 2024 | D4: 2.2 | E4: Egypt | F4: Unemployed | G4: 0 | H4: NO | I4: 14934 | J4: YES | K4: 45825 | L4: Seem shoulder future fall citizen about reveal.
A5: Michelle Ross | B5: Male | C5: 2024 | D5: 3.3 | E5: South Africa | F5: Employed | G5: 428584 | H5: YES | I5: 48164 | J5: YES | K5: 45659 | L5: Just military building different full open.
A6: Sonya Johnston | B6: Male | C6: 2024 | D6: 3.47 | E6: Nigeria | F6: Unemployed | G6: 0 | H6: NO | I6: 0 | J6: NO | L6: Six space couple best issue.
A7: Sherry Wood | B7: Male | C7: 2024 | D7: 3.39 | E7: Nigeria | F7: Unemployed | G7: 0 | H7: NO | I7: 0 | J7: NO | L7: Just myself few worker.
A8: Emily Obrien | B8: Female | C8: 2024 | D8: 3.84 | E8: Egypt | F8: Employed | G8: 400152 | H8: YES | I8: 37346 | J8: YES | K8: 45535 | L8: History office effort remember.
A9: Trevor Young | B9: Male | C9: 2024 | D9: 3.75 | E9: Ghana | F9: Unemployed | G9: 0 | H9: NO | I9: 0 | J9: NO | L9: Different current agency each little.
A10: Angel Perry | B10: Female | C10: 2024 | D10: 4.7 | E10: Nigeria | F10: Unemployed | G10: 0 | H10: NO | I10: 0 | J10: NO | L10: Offer responsibility himself hundred challenge reach throughout team.
A11: Paula Robinson | B11: Male | C11: 2024 | D11: 4.34 | E11: South Africa | F11: Employed | G11: 174118 | H11: NO | I11: 0 | J11: NO | L11: Let newspaper true building card let most.
